Workbook
Name Moneda1: [1]Parametros!$B$17

Sheet 1 Estudiantes
A1: # de paralelos | B1: ='2 Tasa de Retención'!C5 -> 1 | C1: =B1+'2 Tasa de Retención'!D5 -> 3 | D1: =C1+'2 Tasa de Retención'!$C$5 -> 4 | E1: =D1+'2 Tasa de Retención'!$D$5 -> 6 | F1: =E1+'2 Tasa de Retención'!$C$5 -> 7 | G1: =F1+'2 Tasa de Retención'!$D$5 -> 9 | H1: =G1+'2 Tasa de Retención'!$C$5 -> 10 | I1: =H1+'2 Tasa de Retención'!$D$5 -> 12
A3: AÑO | B3: 2023 | C3: 2023 | D3: 2024 | E3: 2024 | F3: 2025 | G3: 2025 | H3: 2026 | I3: 2026
A4: 1 CICLO | B4: ='2 Tasa de Retención'!C10*'2 Tasa de Retención'!C5 -> 30 | C4: =+'2 Tasa de Retención'!D10*'2 Tasa de Retención'!D5 -> 60 | D4: =+B4 -> 30 | E4: =+C4 -> 60 | F4: =+D4 -> 30 | G4: =+E4 -> 60 | H4: =+F4 -> 30 | I4: =+G4 -> 60 | J4: Ret. 65% | S4: =+K4/35 -> 0 | T4: 7
A5: 2 CICLO | C5: =+'2 Tasa de Retención'!E10*'2 Tasa de Retención'!C5 -> 26.94 | D5: =+'2 Tasa de Retención'!F10*'2 Tasa de Retención'!D5 -> 53.88 | E5: =+C5 -> 26.94 | F5: =+D5 -> 53.88 | G5: =+E5 -> 26.94 | H5: =+F5 -> 53.88 | I5: =+E5 -> 26.94 | S5: =+K5/35 -> 0 | T5: 3 | X5: 13565 | Y5: 15553
A6: 3 CICLO | D6: =+'2 Tasa de Retención'!G10*'2 Tasa de Retención'!C5 -> 24.19212 | E6: =+'2 Tasa de Retención'!H10*'2 Tasa de Retención'!D5 -> 48.38424 | F6: =+D6 -> 24.19212 | G6: =+E6 -> 48.38424 | H6: =+F6 -> 24.19212 | I6: =+G6 -> 48.38424 | S6: =+K6/35 -> 0 | T6: 3 | V6: =3*1.5 -> 4.5 | X6: =+X5*2.2% -> 298.43
A7: 4 CICLO | E7: =+'2 Tasa de Retención'!I10*'2 Tasa de Retención'!C5 -> 21.724524 | F7: =+'2 Tasa de Retención'!J10*'2 Tasa de Retención'!D5 -> 43.449048 | G7: =+E7 -> 21.724524 | H7: =+F7 -> 43.449048 | I7: =+G7 -> 21.724524 | S7: =+K7/35 -> 0 | T7: 2 | V7: =+V6*16 -> 72 | X7: =+X6*15.7% -> 46.85351
A8: 5 CICLO | F8: =+'2 Tasa de Retención'!K10*'2 Tasa de Retención'!C5 -> 19.508622 | G8: =+'2 Tasa de Retención'!L10*'2 Tasa de Retención'!D5 -> 39.017245 | H8: =+F8 -> 19.508622 | I8: =+G8 -> 39.017245 | J8: Titu.67% | S8: =+K8/35 -> 0 | T8: 4
A9: 6 CICLO | G9: =+'2 Tasa de Retención'!M10*'2 Tasa de Retención'!C5 -> 18.482469 | H9: =+'2 Tasa de Retención'!N10*'2 Tasa de Retención'!D5 -> 36.964938 | I9: =+G9 -> 18.482469
A10: 7 CICLO | H10: =+'2 Tasa de Retención'!O10*'2 Tasa de Retención'!C5 -> 17.510291 | I10: =+'2 Tasa de Retención'!P10*'2 Tasa de Retención'!D5 -> 35.020582
A11: 8 CICLO | I11: =+'2 Tasa de Retención'!Q10*'2 Tasa de Retención'!C5 -> 17.510291 | S11: =+K11/35 -> 0 | T11: 2
A12: Total Nº de Estudiantes | B12: =SUM(B4:B11) -> 30 | C12: =SUM(C4:C11) -> 86.94 | D12: =SUM(D4:D11) -> 108.07212 | E12: =SUM(E4:E11) -> 157.04876 | F12: =SUM(F4:F11) -> 171.02979 | G12: =SUM(G4:G11) -> 214.54848 | H12: =SUM(H4:H11) -> 225.50502 | I12: =SUM(I4:I11) -> 267.07935
A15: Nº de Horas Clase Docencia Asistida x semana Acumuladas | B15: =+B17 -> 18 | C15: =+B15+C17 -> 60 | D15: =+C15+D17 -> 80 | E15: =+D15+E17 -> 122 | F15: =+E15+F17 -> 143 | G15: =+F15+G17 -> 183 | H15: =+G15+H17 -> 202 | I15: =+H15+I17 -> 234
A16: N° de Horas con Docencia Asistida SEMESTRAL | B16: 288 | C16: 336 | D16: 320 | E16: 336 | F16: 336 | G16: 320 | H16: 304 | I16: =256 -> 256 | K16: =SUM(B16:I16) -> 2496
A17: N° Horas Docencia Asistida por semana y por paralelos | B17: =+B16/16*'2 Tasa de Retención'!$C$5 -> 18 | C17: =(+C16/16)*'2 Tasa de Retención'!$D$5 -> 42 | D17: =(+D16/16)*'2 Tasa de Retención'!$C$5 -> 20 | E17: =(+E16/16)*'2 Tasa de Retención'!$D$5 -> 42 | F17: =(+F16/16)*'2 Tasa de Retención'!$C$5 -> 21 | G17: =(+G16/16)*'2 Tasa de Retención'!$D$5 -> 40 | H17: =(+H16/16)*'2 Tasa de Retención'!$C$5 -> 19 | I17: =(+I16/16)*'2 Tasa de Retención'!$D$5 -> 32
A19: Nº de Horas Clase Aplicac. Práctica x semana Acumuladas | B19: =+B21 -> 10 | C19: =+B19+C21 -> 32 | D19: =+C19+D21 -> 44 | E19: =+D19+E21 -> 70 | F19: =+E19+F21 -> 85 | G19: =+F19+G21 -> 118 | H19: =+G19+H21 -> 139 | I19: =+H19+I21 -> 189 | J19: Relación
A20: N° Horas Aplicación Práctica SEMESTRAL | B20: 160 | C20: 176 | D20: 192 | E20: 208 | F20: 240 | G20: =224+16+24 -> 264 | H20: =240+96 -> 336 | I20: =160+240 -> 400 | J20: 0 | K20: =SUM(B20:I20) -> 1976
A21: N° Horas Aplicación Práctica por semana y por paralelos | B21: =+B20/16*'2 Tasa de Retención'!$C$5 -> 10 | C21: =(+C20/16)*'2 Tasa de Retención'!$D$5 -> 22 | D21: =(+D20/16)*'2 Tasa de Retención'!$C$5 -> 12 | E21: =(+E20/16)*'2 Tasa de Retención'!$D$5 -> 26 | F21: =(+F20/16)*'2 Tasa de Retención'!$C$5 -> 15 | G21: =(+G20/16)*'2 Tasa de Retención'!$D$5 -> 33 | H21: =(+H20/16)*'2 Tasa de Retención'!$C$5 -> 21 | I21: =(+I20/16)*'2 Tasa de Retención'!$D$5 -> 50
J23: Horas Docente
A24: Docentes Requeridos | B24: =+B15/$J$24 -> 1 | C24: =+C15/$J$24 -> 3.3333333 | D24: =+D15/$J$24 -> 4.4444444 | E24: =+E15/$J$24 -> 6.7777778 | F24: =+F15/$J$24 -> 7.9444444 | G24: =+G15/$J$24 -> 10.166667 | H24: =+H15/$J$24 -> 11.222222 | I24: =+I15/$J$24 -> 13 | J24: 18
A25: Tiempo Completo PhD | B25: =+B26*0.4 -> 0.24 | C25: =+C26*0.4 -> 0.8 | D25: =+D26*0.4 -> 1.0666667 | E25: =+E26*0.4 -> 1.6266667 | F25: =+F26*0.4 -> 1.9066667 | G25: =+G26*0.4 -> 2.44 | H25: =+H26*0.4 -> 2.6933333 | I25: =+I26*0.4 -> 3.12
A26: Tiempo Completo Mgs. | B26: =+B24*0.6 -> 0.6 | C26: =+C24*0.6 -> 2 | D26: =+D24*0.6 -> 2.6666667 | E26: =+E24*0.6 -> 4.0666667 | F26: =+F24*0.6 -> 4.7666667 | G26: =+G24*0.6 -> 6.1 | H26: =+H24*0.6 -> 6.7333333 | I26: =+I24*0.6 -> 7.8
A27: Medio Tiempo
A28: Tiempo Parcial | B28: =+B24-B26-B25 -> 0.16 | C28: =+C24-C26-C25 -> 0.53333333 | D28: =+D24-D26-D25 -> 0.71111111 | E28: =+E24-E26-E25 -> 1.0844444 | F28: =+F24-F26-F25 -> 1.2711111 | G28: =+G24-G26-G25 -> 1.6266667 | H28: =+H24-H26-H25 -> 1.7955556 | I28: =+I24-I26-I25 -> 2.08
J29: Horas Tecnico
A30: Ocasional Tipo 2 (Técnico Docente) | B30: =+B19/$J$30 -> 0.25 | C30: =+C19/$J$30 -> 0.8 | D30: =+D19/$J$30 -> 1.1 | E30: =+E19/$J$30 -> 1.75 | F30: =+F19/$J$30 -> 2.125 | G30: =+G19/$J$30 -> 2.95 | H30: =+H19/$J$30 -> 3.475 | I30: =+I19/$J$30 -> 4.725 | J30: 40

Sheet Hoja1
B1: PROYECCION DE ACTIVOS
B2: CUENCA | C2: CUENCA | D2: AZOGUES | E2: CAÑAR | F2: TRONCAL | G2: MACAS | H2: EAD
B3: ACTIVOS AULAS | C3: 13 | D3: 9 | E3: 9 | F3: 9 | G3: 9 | H3: 9
B4: MESAS | C4: =13*25 -> 325 | D4: =9*25 -> 225 | E4: =9*25 -> 225 | F4: =9*25 -> 225 | G4: =9*25 -> 225 | H4: =9*25 -> 225
B5: SILLAS | C5: =+C4 -> 325 | D5: =+D4 -> 225 | E5: =+E4 -> 225 | F5: =+F4 -> 225 | G5: =+G4 -> 225 | H5: =+H4 -> 225 | L5: =54*6 -> 324
B6: PROYECTORES | C6: 13 | D6: =+D3 -> 9 | E6: =+E3 -> 9 | F6: =+F3 -> 9 | G6: =+G3 -> 9 | H6: =+H3 -> 9
B7: PANTALLAS | C7: 13 | D7: =+D3 -> 9 | E7: =+E3 -> 9 | F7: =+F3 -> 9 | G7: =+G3 -> 9 | H7: =+H3 -> 9 | L7: =800/50 -> 16
B8: PISARRAS | C8: 13 | D8: =+D3 -> 9 | E8: =+E3 -> 9 | F8: =+F3 -> 9 | G8: =+G3 -> 9 | H8: =+H3 -> 9 | L8: =16*20 -> 320 | M8: PRESE | N8: =320*9 -> 2880
B9: UTILES DIDACTICOS | L9: =+L7*30 -> 480 | M9: NO PRE | N9: =+N8/13 -> 221.53846
B10: SUMINISTROS DOCENTE | L10: =SUM(L8:L9) -> 800 | N10: =+N9/9 -> 24.615385
B11: CUMPUTADOR | L11: 9 | N11: =+N10*60% -> 14.769231 | O11: 2180 | P11: =+O11*N11 -> 32196.923
B12: MODULO DE TRABAJO | L12: =+L10*L11 -> 7200 | N12: =+N10-N11 -> 9.8461538 | O12: =+O11/2 -> 1090 | P12: =+O12*N12 -> 10732.308
B13: TELEFONO | P13: =SUM(P11:P12) -> 42929.231
B14: IMPRESORA | P14: =+P13*12 -> 515150.77
B15: ADMINISTRACION | P15: =+P14*40% -> 206060.31
B16: CUMPUTADOR | P16: =SUM(P14:P15) -> 721211.08
B17: MODULO DE TRABAJO | P17: =+P16*20% -> 144242.22
B18: TELEFONO | P18: =SUM(P16:P17) -> 865453.29 | Q18: SUELDOS APROX
B19: IMPRESORA | L19: =25*9 -> 225 | M19: =180*14 -> 2520 | N19: =+M19*L19 -> 567000
B20: ARCHIVADORES
B21: OTROS MUEBLES
B22: SECRETARIA | L22: =320/15 -> 21.333333
B23: CUMPUTADOR
B24: MODULO DE TRABAJO
B25: TELEFONO
B26: IMPRESORA
B27: ARCHIVADORES
B28: OTROS MUEBLES
B29: BIBLIOTECA
B30: CUMPUTADOR
B31: MODULO DE TRABAJO
B32: TELEFONO
B33: IMPRESORA
B34: ARCHIVADORES
... B49: OTROS MUEBLES

Sheet 2 Tasa de Retención
B1: SIMULACIÓN DEL COMPORTAMIENTO DE LA GRADUACIÓN | V1: SUMA | W1: PROM | X1: Tasa graduación
A2: tasa x ciclo | C2: 1° | D2: 2° | E2: 3° | K2: 4° | M2: 5° | P2: 6°
A3: 0.9474 | B3: N° alumnoss >>> | C3: 35 | D3: =+C3*A3 -> 33.159 | E3: =+D3*A3 -> 31.414837 | K3: =+E3*A3 -> 29.762416 | M3: =+K3*A3 -> 28.196913 | P3: =+M3*A3 -> 26.713755 | V3: =SUM(C3:T3) -> 184.24692 | W3: =+V3/9 -> 20.47188 | X3: 0.6657
C4: abr | D4: sep
B5: Paralelos >>> | C5: 1 | D5: 2
B6: SIMULACIÓN DEL COMPORTAMIENTO DE LA RETENCIÓN
C7: 1° | D7: 1° | E7: 2° | F7: 2° | G7: 3° | H7: 3° | I7: 4° | J7: 4° | K7: 5° | L7: 5° | M7: 6° | N7: 6° | O7: 7° | P7: 7° | Q7: 8°
B8: 0.898 | K8: 0.9474
P9: =+M9*B8 -> 0 | Q9: =+P9*C8 -> 0 | W9: Tasa de retención | AC9: =24/30 -> 0.8
B10: N° Alumnos >>> | C10: 30 | D10: 30 | E10: =+C10*B8 -> 26.94 | F10: =+D10*B8 -> 26.94 | G10: =+E10*B8 -> 24.19212 | H10: =+F10*B8 -> 24.19212 | I10: =+G10*B8 -> 21.724524 | J10: =+H10*B8 -> 21.724524 | K10: =+B8*I10 -> 19.508622 | L10: =+B8*J10 -> 19.508622 | M10: =+K10*K8 -> 18.482469 | N10: =+L10*K8 -> 18.482469 | O10: =+M10*K8 -> 17.510291 | P10: =+N10*K8 -> 17.510291 | Q10: =+O10 -> 17.510291 | V10: =SUM(C10:T10) -> 334.22634 | W10: =+V10/9 -> 37.13626 | X10: 0.65 | Y10: (Primero y arranque de 3° ciclo)
C11: Retención | K11: Graduación
M12: =+C10*0.64 -> 19.2 | S12: =+M12*0.283 -> 5.4336 | X12: 51
B13: NOTA: SE RECOMIENDA TOMAR LA SIMULACIÓN DE LA RETENCIÓN (ESTA INVOLUCRA A LAS DOS) | S13: =+M10*0.33 -> 6.0992147 | X13: 0
S14: 78 | X14: 78
J15: =+K10/C10 -> 0.65028741 | K15: =+Q10/K10 -> 0.89756676 | X15: 81
B16: REFERENCIA A LOS CRITERIOS DE ACREDITACIÓN: Indicador: Utilidad vs % de cumplimiento | J16: =+L10/D10 -> 0.65028741 | K16: =+P10/L10 -> 0.89756676
C18: GRADUACIÓN | K18: RETENCIÓN
C20: X | D20: Y | K20: X | M20: Y
C21: 0.001 | D21: 0 | K21: 0.1 | M21: 0.1 | N21: 0
C22: 14.9 | D22: 0 | K22: 59 | M22: 0.59
C23: 15 | D23: 1 | K23: 60 | M23: 1
C24: 60 | D24: 1 | K24: 70 | M24: 1
C25: 60.1 | D25: 0 | K25: 80 | M25: 1
C26: 100 | D26: 0 | K26: 100 | M26: 1

Sheet 3 Recursos físicos
A1: ACTIVOS FIJOS
A2: DESGLOSE DE SITUACIÓN INICIAL
A3: DESCRIPCIÓN | B3: CANTIDAD | C3: UNIDAD | D3: VALOR UNITARIO | E3: VALOR TOTAL
A4: Muebles y enseres | E4: =SUM(E5:E21) -> 0 | O4: 76853.06 | P4: =+O4/2 -> 38426.53
A5: Silla giratoria | B5: 0 | C5: UNI | D5: 192 | E5: =+D5*B5 -> 0 | O5: 123000 | P5: =+O5/2 -> 61500
A6: Silla de espera | B6: =+B5 -> 0 | C6: UNI | D6: 45 | E6: =+D6*B6 -> 0
A7: Archivador de madera | B7: =+B5 -> 0 | C7: UNI | D7: 150 | E7: =+D7*B7 -> 0
A8: Escritorio docentes | B8: =+B5 -> 0 | C8: UNI | D8: 306 | E8: =+D8*B8 -> 0
A9: Mesas de laboratorio | C9: UNI | D9: 250 | E9: =+D9*B9 -> 0
A10: Libros | C10: UNI | E10: =+D10*B10 -> 0
C11: UNI | D11: 60 | E11: =+D11*B11 -> 0
C12: UNI | D12: 30 | E12: =+D12*B12 -> 0
C13: UNI | D13: 150 | E13: =+D13*B13 -> 0
E14: =+D14*B14 -> 0
E15: =+D15*B15 -> 0
E16: =+D16*B16 -> 0
E17: =+D17*B17 -> 0
E18: =+D18*B18 -> 0
E19: =+D19*B19 -> 0
E20: =+D20*B20 -> 0
E21: =+D21*B21 -> 0
A22: Laboratorios y Equipos | E22: =SUM(E23:E39) -> 376.875
A23: Operatividad EVEA | B23: =+'1 Estudiantes'!B12 -> 30 | C23: UNI | D23: 7.5 | E23: =+B23*D23 -> 225
A24: Licencias, almacenamiento y webninar ZOOM | B24: =+'5 Demanda'!B20+10 -> 11.25 | C24: UNI | D24: 13.5 | E24: =+B24*D24 -> 151.875
A25: Laboratorio de Redes | C25: UNI | D25: 25000 | E25: =+B25*D25 -> 0
A26: Laboratorio de Redes | C26: UNI | D26: 25000 | E26: =+B26*D26 -> 0
C27: UNI | D27: 1105 | E27: =+B27*D27 -> 0
C28: UNI | D28: 1100 | E28: =+B28*D28 -> 0
A29: Equipo de audio | C29: UNI | D29: 80 | E29: =+B29*D29 -> 0
C30: UNI | D30: 1280 | E30: =+B30*D30 -> 0
E31: =+B31*D31 -> 0
E32: =+B32*D32 -> 0
E33: =+B33*D33 -> 0
E34: =+B34*D34 -> 0
E35: =+B35*D35 -> 0
E36: =+B36*D36 -> 0
E37: =+B37*D37 -> 0
E38: =+B38*D38 -> 0
E39: =+D39*B39*F39 -> 0
A40: Equipo de Computo | E40: =SUM(E41:E55) -> 1200
...

Sheet 4 Inversión Inicial
A1: RESUMEN INVERSIÓN INICIAL
A2: TIPO DE INVERSIÓN | B2: VALOR | C2: MONTO TOTAL
A3: ACTIVOS DIFERIDOS | C3: =SUM(B4:B4) -> 300
A4: Permiso Municipal y Bomberos | B4: ='Amortización '!B3 -> 300
A5: ACTIVOS FIJOS | C5: =SUM(B6:B9) -> 1576.875
A6: =+'3 Recursos físicos'!A4 -> Muebles y enseres | B6: =+'3 Recursos físicos'!E4 -> 0
A7: =+'3 Recursos físicos'!A22 -> Laboratorios y Equipos | B7: =+'3 Recursos físicos'!E22 -> 376.875
A8: =+'3 Recursos físicos'!A40 -> Equipo de Computo | B8: =+'3 Recursos físicos'!E40 -> 1200
A9: =+'3 Recursos físicos'!A56 -> Equipo de Oficina | B9: =+'3 Recursos físicos'!E56 -> 0
A10: TOTAL ACTIVOS | C10: =+C3+C5 -> 1876.875
A11: CAPITAL DE TRABAJO (2 meses) | B11: =+'6 Capital de trabajo'!D48*2 -> 16163.628
A12: Imprevistos 5% | B12: =+B11*5% -> 808.18139
A13: TOTAL DE INVERSION INICIAL | C13: =+C10+B11+B12 -> 18848.684

Sheet 6 Capital de trabajo
A1: CAPITAL DE TRABAJO
A2: CANTIDAD | B2: CONCEPTO | C2: VALOR UNITARIO | D2: VALOR MENSUAL
A3: GASTOS DE SERVICIO Y ADMINISTRACIÓN
A4: =+'7 Sueldos'!C3 -> 1 | B4: Decano | C4: 3880 | D4: =+'7 Sueldos'!K3/6 -> 490.87213
A5: =+'7 Sueldos'!C4 -> 1 | B5: Subdecano | C5: 2880 | D5: =+'7 Sueldos'!K4/6 -> 365.17689
A6: =+'7 Sueldos'!C5 -> 1 | B6: Director de Carrera | C6: 2200 | D6: =+'7 Sueldos'!K5/6 -> 2936.8933
A7: =+'7 Sueldos'!C6 -> 1 | B7: Secretario | C7: 1000 | D7: =+'7 Sueldos'!K6/6 -> 128.86984
A8: =+'7 Sueldos'!C7 -> 1 | B8: Auxiliar de Secretaria | C8: 850 | D8: =+'7 Sueldos'!K7/6 -> 110.01556
A9: =+'7 Sueldos'!C8 -> 1 | B9: Coordinador | C9: 900 | D9: =+'7 Sueldos'!K8/6 -> 116.30032
A10: =+'7 Sueldos'!C9 -> 1 | B10: Bienestar Estudiantil | C10: 900 | D10: =+'7 Sueldos'!K9/6 -> 116.30032
A11: =+'7 Sueldos'!C10 -> 0.24 | B11: =+'1 Estudiantes'!A25 -> Tiempo Completo PhD | C11: 2800 | D11: =+'7 Sueldos'!K10/6 -> 894.9056
A12: =+'7 Sueldos'!C11 -> 0.6 | B12: =+'1 Estudiantes'!A26 -> Tiempo Completo Mgs. | C12: 1800 | D12: =+'7 Sueldos'!K11/6 -> 1445.384
A13: =+'7 Sueldos'!C12 -> 0 | B13: =+'1 Estudiantes'!A27 -> Medio Tiempo | C13: =+C12/2 -> 900 | D13: =+'7 Sueldos'!K12/6 -> 0 | E13: Valor Hora Clase | F13: 12
A14: =+'7 Sueldos'!C13 -> 0.16 | B14: =+'1 Estudiantes'!A28 -> Tiempo Parcial | C14: =+F13*F14 -> 432 | D14: =+'7 Sueldos'!K13/6 -> 96.557909 | E14: Horas clase/MES | F14: =9*4 -> 36
A15: =+'7 Sueldos'!C14 -> 0.25 | B15: =+'1 Estudiantes'!A30 -> Ocasional Tipo 2 (Técnico Docente) | C15: 1350 | D15: =+'7 Sueldos'!K14/6 -> 453.76583
A16: =+'7 Sueldos'!C15 -> 1 | B16: Bibliotecario | C16: 800 | D16: =+'7 Sueldos'!K15/6 -> 103.73079
A17: =+'7 Sueldos'!C16 -> 2 | B17: Auxiliar de Servicio | C17: 450 | D17: =+'7 Sueldos'!K16/6 -> 119.47492
A18: =+'7 Sueldos'!C17 -> 1 | B18: Guardia | C18: 650 | D18: =+'7 Sueldos'!K17/6 -> 84.876508
B19: TOTAL | D19: =SUM(D4:D18) -> 7463.1239
A20: MATERIALES Y SUMINISTROS
A21: =+'5 Demanda'!B53 -> 6 | B21: Resma de papel bond de 75 gramos | C21: 3.25 | D21: =+C21*A21 -> 19.5
A22: =+'5 Demanda'!B54 -> 0.6 | B22: Cartuchos de impresora (Color) | C22: 50 | D22: =+C22*A22 -> 30
A23: =+'5 Demanda'!B55 -> 0.6 | B23: Cartuchos de impresora (Negro) | C23: 40 | D23: =+C23*A23 -> 24
A24: =+'5 Demanda'!B56 -> 60 | B24: Carpetas de cartón | C24: 1 | D24: =+C24*A24 -> 60
A25: =+'5 Demanda'!B57 -> 30 | B25: Porta files | C25: 2 | D25: =+C25*A25 -> 60
A26: =+'5 Demanda'!B58 -> 30 | B26: Esferos, micro minas, lápiz, borradores, correctores | C26: 0.25 | D26: =+C26*A26 -> 7.5
A27: =+'5 Demanda'!B59 -> 0.6 | B27: Grapas, clips (CAJA) | C27: 1 | D27: =+C27*A27 -> 0.6
B28: TOTAL | D28: =SUM(D20:D27) -> 201.6
A29: SUMINISTROS DE ASEO Y LIMPIEZA
A30: =+'5 Demanda'!B61 -> 0.9 | B30: Desinfectante (Galón) | C30: 4 | D30: =+C30*A30 -> 3.6
A31: =+'5 Demanda'!B62 -> 1.08 | B31: Jabón Líquido (Galón) | C31: 3 | D31: =+C31*A31 -> 3.24
A32: =+'5 Demanda'!B63 -> 23.4 | B32: Papel Higiénico (Rollo Grande) | C32: 10.5 | D32: =+C32*A32 -> 245.7
A33: =+'5 Demanda'!B64 -> 2 | B33: Escoba | C33: 10.5 | D33: =+C33*A33 -> 21
A34: =+'5 Demanda'!B65 -> 6 | B34: Paquete de Fundas de Basura | C34: 0.8 | D34: =+C34*A34 -> 4.8
A35: =+'5 Demanda'!B66 -> 3 | B35: Trapeador | C35: 2.5 | D35: =+C35*A35 -> 7.5
A36: =+'5 Demanda'!B67 -> 0.9 | B36: Cloro (Galón) | C36: 2.5 | D36: =+C36*A36 -> 2.25
B37: TOTAL | D37: =SUM(D30:D35) -> 285.84
A38: ACCESORIOS Y MATERIALES
A39: 1 | D39: =+C39*A39 -> 0
A40: =+'5 Demanda'!B69 -> 5.25 | B40: Grapadora | C40: 15 | D40: =+C40*A40 -> 78.75
...

Sheet Depreciación
A1: DESCRIPCION | B1: VALOR | C1: VALOR RESIDUAL | D1: TIEMPO | E1: DEPRECIACION | N1: DEPRECIACION ACUMULADA
E2: =+'1 Estudiantes'!B3 -> 2023 | F2: =+'1 Estudiantes'!C3 -> 2023 | G2: =+'1 Estudiantes'!D3 -> 2024 | H2: =+'1 Estudiantes'!E3 -> 2024 | I2: =+'1 Estudiantes'!F3 -> 2025 | J2: =+'1 Estudiantes'!G3 -> 2025 | K2: =+'1 Estudiantes'!H3 -> 2026 | L2: =+'1 Estudiantes'!I3 -> 2026 | N2: =+F2 -> 2023 | O2: =+G2 -> 2024 | P2: =+H2 -> 2024 | Q2: =+I2 -> 2025 | R2: =+J2 -> 2025 | S2: =+K2 -> 2026 | T2: =+L2 -> 2026
A3: =+'3 Recursos físicos'!A4 -> Muebles y enseres | E3: =SUM(E4:E20) -> 0 | F3: =SUM(F4:F20) -> 0 | G3: =SUM(G4:G20) -> 0 | H3: =SUM(H4:H20) -> 0 | I3: =SUM(I4:I20) -> 0 | J3: =SUM(J4:J20) -> 0 | K3: =SUM(K4:K20) -> 0 | L3: =SUM(L4:L20) -> 0 | N3: =SUM(N4:N20) -> 0 | O3: =SUM(O4:O20) -> 0 | P3: =SUM(P4:P20) -> 0 | Q3: =SUM(Q4:Q20) -> 0 | R3: =SUM(R4:R20) -> 0 | S3: =SUM(S4:S20) -> 0 | T3: =SUM(T4:T20) -> 0
A4: =+'3 Recursos físicos'!A5 -> Silla giratoria | B4: =+'3 Recursos físicos'!E5 -> 0 | C4: =+B4*5% -> 0 | D4: 10 | E4: =+(B4-C4)/D4 -> 0 | F4: =+E4/2 -> 0 | G4: =+F4 -> 0 | H4: =+G4 -> 0 | I4: =+H4 -> 0 | J4: =+I4 -> 0 | K4: =+J4 -> 0 | L4: =+K4 -> 0 | N4: =+G4+(('3 Recursos físicos'!C127*0.95)/Depreciación!$D4) -> 0 | O4: =+H4+(('3 Recursos físicos'!D127*0.95)/Depreciación!$D4) -> 0 | P4: =+I4+(('3 Recursos físicos'!E127*0.95)/Depreciación!$D4) -> 0 | Q4: =+J4+(('3 Recursos físicos'!F127*0.95)/Depreciación!$D4) -> 0 | R4: =+K4+(('3 Recursos físicos'!G127*0.95)/Depreciación!$D4) -> 0 | S4: =+L4+(('3 Recursos físicos'!H127*0.95)/Depreciación!$D4) -> 0 | T4: =+F4+(('3 Recursos físicos'!I127*0.95)/Depreciación!$D4) -> 0
A5: =+'3 Recursos físicos'!A6 -> Silla de espera | B5: =+'3 Recursos físicos'!E6 -> 0 | C5: =+B5*5% -> 0 | D5: 10 | E5: =+(B5-C5)/D5 -> 0 | F5: =+E5/2 -> 0 | G5: =+F5 -> 0 | H5: =+G5 -> 0 | I5: =+H5 -> 0 | J5: =+I5 -> 0 | K5: =+J5 -> 0 | L5: =+K5 -> 0 | N5: =+G5+(('3 Recursos físicos'!C128*0.95)/Depreciación!$D5) -> 0 | O5: =+H5+(('3 Recursos físicos'!D128*0.95)/Depreciación!$D5) -> 0 | P5: =+I5+(('3 Recursos físicos'!E128*0.95)/Depreciación!$D5) -> 0 | Q5: =+J5+(('3 Recursos físicos'!F128*0.95)/Depreciación!$D5) -> 0 | R5: =+K5+(('3 Recursos físicos'!G128*0.95)/Depreciación!$D5) -> 0 | S5: =+L5+(('3 Recursos físicos'!H128*0.95)/Depreciación!$D5) -> 0 | T5: =+F5+(('3 Recursos físicos'!I128*0.95)/Depreciación!$D5) -> 0
A6: =+'3 Recursos físicos'!A7 -> Archivador de madera | B6: =+'3 Recursos físicos'!E7 -> 0 | C6: =+B6*5% -> 0 | D6: 10 | E6: =+(B6-C6)/D6 -> 0 | F6: =+E6/2 -> 0 | G6: =+F6 -> 0 | H6: =+G6 -> 0 | I6: =+H6 -> 0 | J6: =+I6 -> 0 | K6: =+J6 -> 0 | L6: =+K6 -> 0 | N6: =+G6+(('3 Recursos físicos'!C129*0.95)/Depreciación!$D6) -> 0 | O6: =+H6+(('3 Recursos físicos'!D129*0.95)/Depreciación!$D6) -> 0 | P6: =+I6+(('3 Recursos físicos'!E129*0.95)/Depreciación!$D6) -> 0 | Q6: =+J6+(('3 Recursos físicos'!F129*0.95)/Depreciación!$D6) -> 0 | R6: =+K6+(('3 Recursos físicos'!G129*0.95)/Depreciación!$D6) -> 0 | S6: =+L6+(('3 Recursos físicos'!H129*0.95)/Depreciación!$D6) -> 0 | T6: =+F6+(('3 Recursos físicos'!I129*0.95)/Depreciación!$D6) -> 0
A7: =+'3 Recursos físicos'!A8 -> Escritorio docentes | B7: =+'3 Recursos físicos'!E8 -> 0 | C7: =+B7*5% -> 0 | D7: 10 | E7: =+(B7-C7)/D7 -> 0 | F7: =+E7/2 -> 0 | G7: =+F7 -> 0 | H7: =+G7 -> 0 | I7: =+H7 -> 0 | J7: =+I7 -> 0 | K7: =+J7 -> 0 | L7: =+K7 -> 0 | N7: =+G7+(('3 Recursos físicos'!C130*0.95)/Depreciación!$D7) -> 0 | O7: =+H7+(('3 Recursos físicos'!D130*0.95)/Depreciación!$D7) -> 0 | P7: =+I7+(('3 Recursos físicos'!E130*0.95)/Depreciación!$D7) -> 0 | Q7: =+J7+(('3 Recursos físicos'!F130*0.95)/Depreciación!$D7) -> 0 | R7: =+K7+(('3 Recursos físicos'!G130*0.95)/Depreciación!$D7) -> 0 | S7: =+L7+(('3 Recursos físicos'!H130*0.95)/Depreciación!$D7) -> 0 | T7: =+F7+(('3 Recursos físicos'!I130*0.95)/Depreciación!$D7) -> 0
A8: =+'3 Recursos físicos'!A9 -> Mesas de laboratorio | B8: =+'3 Recursos físicos'!E9 -> 0 | C8: =+B8*5% -> 0 | D8: 10 | E8: =+(B8-C8)/D8 -> 0 | F8: =+E8/2 -> 0 | G8: =+F8 -> 0 | H8: =+G8 -> 0 | I8: =+H8 -> 0 | J8: =+I8 -> 0 | K8: =+J8 -> 0 | L8: =+K8 -> 0 | N8: =+G8+(('3 Recursos físicos'!C131*0.95)/Depreciación!$D8) -> 0 | O8: =+H8+(('3 Recursos físicos'!D131*0.95)/Depreciación!$D8) -> 0 | P8: =+I8+(('3 Recursos físicos'!E131*0.95)/Depreciación!$D8) -> 0 | Q8: =+J8+(('3 Recursos físicos'!F131*0.95)/Depreciación!$D8) -> 0 | R8: =+K8+(('3 Recursos físicos'!G131*0.95)/Depreciación!$D8) -> 0 | S8: =+L8+(('3 Recursos físicos'!H131*0.95)/Depreciación!$D8) -> 0 | T8: =+F8+(('3 Recursos físicos'!I131*0.95)/Depreciación!$D8) -> 0
A9: =+'3 Recursos físicos'!A10 -> Libros | B9: =+'3 Recursos físicos'!E10 -> 0 | C9: =+B9*5% -> 0 | D9: 10 | E9: =+(B9-C9)/D9 -> 0 | F9: =+E9/2 -> 0 | G9: =+F9 -> 0 | H9: =+G9 -> 0 | I9: =+H9 -> 0 | J9: =+I9 -> 0 | K9: =+J9 -> 0 | L9: =+K9 -> 0 | N9: =+G9+(('3 Recursos físicos'!C132*0.95)/Depreciación!$D9) -> 0 | O9: =+H9+(('3 Recursos físicos'!D132*0.95)/Depreciación!$D9) -> 0 | P9: =+I9+(('3 Recursos físicos'!E132*0.95)/Depreciación!$D9) -> 0 | Q9: =+J9+(('3 Recursos físicos'!F132*0.95)/Depreciación!$D9) -> 0 | R9: =+K9+(('3 Recursos físicos'!G132*0.95)/Depreciación!$D9) -> 0 | S9: =+L9+(('3 Recursos físicos'!H132*0.95)/Depreciación!$D9) -> 0 | T9: =+F9+(('3 Recursos físicos'!I132*0.95)/Depreciación!$D9) -> 0
A10: =+'3 Recursos físicos'!#REF! -> #REF! | B10: =+'3 Recursos físicos'!E11 -> 0 | C10: =+B10*5% -> 0 | D10: 1 | E10: =+(B10-C10)/D10 -> 0 | F10: =+E10/2 -> 0 | G10: =+F10 -> 0 | H10: =+G10 -> 0 | I10: =+H10 -> 0 | J10: =+I10 -> 0 | K10: =+J10 -> 0 | L10: =+K10 -> 0 | N10: =+G10+(('3 Recursos físicos'!C133*0.95)/Depreciación!$D10) -> 0 | O10: =+H10+(('3 Recursos físicos'!D133*0.95)/Depreciación!$D10) -> 0 | P10: =+I10+(('3 Recursos físicos'!E133*0.95)/Depreciación!$D10) -> 0 | Q10: =+J10+(('3 Recursos físicos'!F133*0.95)/Depreciación!$D10) -> 0 | R10: =+K10+(('3 Recursos físicos'!G133*0.95)/Depreciación!$D10) -> 0 | S10: =+L10+(('3 Recursos físicos'!H133*0.95)/Depreciación!$D10) -> 0 | T10: =+F10+(('3 Recursos físicos'!I133*0.95)/Depreciación!$D10) -> 0
A11: =+'3 Recursos físicos'!#REF! -> #REF! | B11: =+'3 Recursos físicos'!E12 -> 0 | C11: =+B11*5% -> 0 | D11: 10 | E11: =+(B11-C11)/D11 -> 0 | F11: =+E11/2 -> 0 | G11: =+F11 -> 0 | H11: =+G11 -> 0 | I11: =+H11 -> 0 | J11: =+I11 -> 0 | K11: =+J11 -> 0 | L11: =+K11 -> 0 | N11: =+G11+(('3 Recursos físicos'!C134*0.95)/Depreciación!$D11) -> 0 | O11: =+H11+(('3 Recursos físicos'!D134*0.95)/Depreciación!$D11) -> 0 | P11: =+I11+(('3 Recursos físicos'!E134*0.95)/Depreciación!$D11) -> 0 | Q11: =+J11+(('3 Recursos físicos'!F134*0.95)/Depreciación!$D11) -> 0 | R11: =+K11+(('3 Recursos físicos'!G134*0.95)/Depreciación!$D11) -> 0 | S11: =+L11+(('3 Recursos físicos'!H134*0.95)/Depreciación!$D11) -> 0 | T11: =+F11+(('3 Recursos físicos'!I134*0.95)/Depreciación!$D11) -> 0
A12: =+'3 Recursos físicos'!#REF! -> #REF! | B12: =+'3 Recursos físicos'!E13 -> 0 | C12: =+B12*5% -> 0 | D12: 10 | E12: =+(B12-C12)/D12 -> 0 | F12: =+E12/2 -> 0 | G12: =+F12 -> 0 | H12: =+G12 -> 0 | I12: =+H12 -> 0 | J12: =+I12 -> 0 | K12: =+J12 -> 0 | L12: =+K12 -> 0 | N12: =+G12+(('3 Recursos físicos'!C135*0.95)/Depreciación!$D12) -> 0 | O12: =+H12+(('3 Recursos físicos'!D135*0.95)/Depreciación!$D12) -> 0 | P12: =+I12+(('3 Recursos físicos'!E135*0.95)/Depreciación!$D12) -> 0 | Q12: =+J12+(('3 Recursos físicos'!F135*0.95)/Depreciación!$D12) -> 0 | R12: =+K12+(('3 Recursos físicos'!G135*0.95)/Depreciación!$D12) -> 0 | S12: =+L12+(('3 Recursos físicos'!H135*0.95)/Depreciación!$D12) -> 0 | T12: =+F12+(('3 Recursos físicos'!I135*0.95)/Depreciación!$D12) -> 0
A13: =+'3 Recursos físicos'!#REF! -> #REF! | B13: =+'3 Recursos físicos'!E14 -> 0 | C13: =+B13*5% -> 0 | D13: 10 | E13: =+(B13-C13)/D13 -> 0 | F13: =+E13/2 -> 0 | G13: =+F13 -> 0 | H13: =+G13 -> 0 | I13: =+H13 -> 0 | J13: =+I13 -> 0 | K13: =+J13 -> 0 | L13: =+K13 -> 0 | N13: =+G13+(('3 Recursos físicos'!C136*0.95)/Depreciación!$D13) -> 0 | O13: =+H13+(('3 Recursos físicos'!D136*0.95)/Depreciación!$D13) -> 0 | P13: =+I13+(('3 Recursos físicos'!E136*0.95)/Depreciación!$D13) -> 0 | Q13: =+J13+(('3 Recursos físicos'!F136*0.95)/Depreciación!$D13) -> 0 | R13: =+K13+(('3 Recursos físicos'!G136*0.95)/Depreciación!$D13) -> 0 | S13: =+L13+(('3 Recursos físicos'!H136*0.95)/Depreciación!$D13) -> 0 | T13: =+F13+(('3 Recursos físicos'!I136*0.95)/Depreciación!$D13) -> 0
A14: =+'3 Recursos físicos'!A10 -> Libros | B14: =+'3 Recursos físicos'!E15 -> 0 | C14: =+B14*5% -> 0 | D14: 10 | E14: =+(B14-C14)/D14 -> 0 | F14: =+E14/2 -> 0 | G14: =+F14 -> 0 | H14: =+G14 -> 0 | I14: =+H14 -> 0 | J14: =+I14 -> 0 | K14: =+J14 -> 0 | L14: =+K14 -> 0 | N14: =+G14+(('3 Recursos físicos'!C137*0.95)/Depreciación!$D14) -> 0 | O14: =+H14+(('3 Recursos físicos'!D137*0.95)/Depreciación!$D14) -> 0 | P14: =+I14+(('3 Recursos físicos'!E137*0.95)/Depreciación!$D14) -> 0 | Q14: =+J14+(('3 Recursos físicos'!F137*0.95)/Depreciación!$D14) -> 0 | R14: =+K14+(('3 Recursos físicos'!G137*0.95)/Depreciación!$D14) -> 0 | S14: =+L14+(('3 Recursos físicos'!H137*0.95)/Depreciación!$D14) -> 0 | T14: =+F14+(('3 Recursos físicos'!I137*0.95)/Depreciación!$D14) -> 0
A15: =+'3 Recursos físicos'!A11 -> 0 | B15: =+'3 Recursos físicos'!E16 -> 0 | C15: =+B15*5% -> 0 | D15: 10 | E15: =+(B15-C15)/D15 -> 0 | F15: =+E15/2 -> 0 | G15: =+F15 -> 0 | H15: =+G15 -> 0 | I15: =+H15 -> 0 | J15: =+I15 -> 0 | K15: =+J15 -> 0 | L15: =+K15 -> 0 | N15: =+G15+(('3 Recursos físicos'!C138*0.95)/Depreciación!$D15) -> 0 | O15: =+H15+(('3 Recursos físicos'!D138*0.95)/Depreciación!$D15) -> 0 | P15: =+I15+(('3 Recursos físicos'!E138*0.95)/Depreciación!$D15) -> 0 | Q15: =+J15+(('3 Recursos físicos'!F138*0.95)/Depreciación!$D15) -> 0 | R15: =+K15+(('3 Recursos físicos'!G138*0.95)/Depreciación!$D15) -> 0 | S15: =+L15+(('3 Recursos físicos'!H138*0.95)/Depreciación!$D15) -> 0 | T15: =+F15+(('3 Recursos físicos'!I138*0.95)/Depreciación!$D15) -> 0
A16: =+'3 Recursos físicos'!A12 -> 0 | B16: =+'3 Recursos físicos'!E17 -> 0 | C16: =+B16*5% -> 0 | D16: 10 | E16: =+(B16-C16)/D16 -> 0 | F16: =+E16/2 -> 0 | G16: =+F16 -> 0 | H16: =+G16 -> 0 | I16: =+H16 -> 0 | J16: =+I16 -> 0 | K16: =+J16 -> 0 | L16: =+K16 -> 0 | N16: =+G16+(('3 Recursos físicos'!C139*0.95)/Depreciación!$D16) -> 0 | O16: =+H16+(('3 Recursos físicos'!D139*0.95)/Depreciación!$D16) -> 0 | P16: =+I16+(('3 Recursos físicos'!E139*0.95)/Depreciación!$D16) -> 0 | Q16: =+J16+(('3 Recursos físicos'!F139*0.95)/Depreciación!$D16) -> 0 | R16: =+K16+(('3 Recursos físicos'!G139*0.95)/Depreciación!$D16) -> 0 | S16: =+L16+(('3 Recursos físicos'!H139*0.95)/Depreciación!$D16) -> 0 | T16: =+F16+(('3 Recursos físicos'!I139*0.95)/Depreciación!$D16) -> 0
A17: =+'3 Recursos físicos'!A13 -> 0 | B17: =+'3 Recursos físicos'!E18 -> 0 | C17: =+B17*5% -> 0 | D17: 10 | E17: =+(B17-C17)/D17 -> 0 | F17: =+E17/2 -> 0 | G17: =+F17 -> 0 | H17: =+G17 -> 0 | I17: =+H17 -> 0 | J17: =+I17 -> 0 | K17: =+J17 -> 0 | L17: =+K17 -> 0 | N17: =+G17+(('3 Recursos físicos'!C140*0.95)/Depreciación!$D17) -> 0 | O17: =+H17+(('3 Recursos físicos'!D140*0.95)/Depreciación!$D17) -> 0 | P17: =+I17+(('3 Recursos físicos'!E140*0.95)/Depreciación!$D17) -> 0 | Q17: =+J17+(('3 Recursos físicos'!F140*0.95)/Depreciación!$D17) -> 0 | R17: =+K17+(('3 Recursos físicos'!G140*0.95)/Depreciación!$D17) -> 0 | S17: =+L17+(('3 Recursos físicos'!H140*0.95)/Depreciación!$D17) -> 0 | T17: =+F17+(('3 Recursos físicos'!I140*0.95)/Depreciación!$D17) -> 0
A18: =+'3 Recursos físicos'!A14 -> 0 | B18: =+'3 Recursos físicos'!E19 -> 0 | C18: =+B18*5% -> 0 | D18: 10 | E18: =+(B18-C18)/D18 -> 0 | F18: =+E18/2 -> 0 | G18: =+F18 -> 0 | H18: =+G18 -> 0 | I18: =+H18 -> 0 | J18: =+I18 -> 0 | K18: =+J18 -> 0 | L18: =+K18 -> 0 | N18: =+G18+(('3 Recursos físicos'!C141*0.95)/Depreciación!$D18) -> 0 | O18: =+H18+(('3 Recursos físicos'!D141*0.95)/Depreciación!$D18) -> 0 | P18: =+I18+(('3 Recursos físicos'!E141*0.95)/Depreciación!$D18) -> 0 | Q18: =+J18+(('3 Recursos físicos'!F141*0.95)/Depreciación!$D18) -> 0 | R18: =+K18+(('3 Recursos físicos'!G141*0.95)/Depreciación!$D18) -> 0 | S18: =+L18+(('3 Recursos físicos'!H141*0.95)/Depreciación!$D18) -> 0 | T18: =+F18+(('3 Recursos físicos'!I141*0.95)/Depreciación!$D18) -> 0
A19: =+'3 Recursos físicos'!A15 -> 0 | B19: =+'3 Recursos físicos'!E20 -> 0 | C19: =+B19*5% -> 0 | D19: 10 | E19: =+(B19-C19)/D19 -> 0 | F19: =+E19/2 -> 0 | G19: =+F19 -> 0 | H19: =+G19 -> 0 | I19: =+H19 -> 0 | J19: =+I19 -> 0 | K19: =+J19 -> 0 | L19: =+K19 -> 0 | N19: =+G19+(('3 Recursos físicos'!C142*0.95)/Depreciación!$D19) -> 0 | O19: =+H19+(('3 Recursos físicos'!D142*0.95)/Depreciación!$D19) -> 0 | P19: =+I19+(('3 Recursos físicos'!E142*0.95)/Depreciación!$D19) -> 0 | Q19: =+J19+(('3 Recursos físicos'!F142*0.95)/Depreciación!$D19) -> 0 | R19: =+K19+(('3 Recursos físicos'!G142*0.95)/Depreciación!$D19) -> 0 | S19: =+L19+(('3 Recursos físicos'!H142*0.95)/Depreciación!$D19) -> 0 | T19: =+F19+(('3 Recursos físicos'!I142*0.95)/Depreciación!$D19) -> 0
A20: =+'3 Recursos físicos'!A16 -> 0 | B20: =+'3 Recursos físicos'!E21 -> 0 | C20: =+B20*5% -> 0 | D20: 10 | E20: =+(B20-C20)/D20 -> 0 | F20: =+E20/2 -> 0 | G20: =+F20 -> 0 | H20: =+G20 -> 0 | I20: =+H20 -> 0 | J20: =+I20 -> 0 | K20: =+J20 -> 0 | L20: =+K20 -> 0 | N20: =+G20+(('3 Recursos físicos'!C143*0.95)/Depreciación!$D20) -> 0 | O20: =+H20+(('3 Recursos físicos'!D143*0.95)/Depreciación!$D20) -> 0 | P20: =+I20+(('3 Recursos físicos'!E143*0.95)/Depreciación!$D20) -> 0 | Q20: =+J20+(('3 Recursos físicos'!F143*0.95)/Depreciación!$D20) -> 0 | R20: =+K20+(('3 Recursos físicos'!G143*0.95)/Depreciación!$D20) -> 0 | S20: =+L20+(('3 Recursos físicos'!H143*0.95)/Depreciación!$D20) -> 0 | T20: =+F20+(('3 Recursos físicos'!I143*0.95)/Depreciación!$D20) -> 0
A21: =+'3 Recursos físicos'!A22 -> Laboratorios y Equipos | E21: =SUM(E22:E34) -> 35.803125 | F21: =SUM(F22:F34) -> 17.901563 | G21: =SUM(G22:G34) -> 17.901563 | H21: =SUM(H22:H34) -> 17.901563 | I21: =SUM(I22:I34) -> 17.901563 | J21: =SUM(J22:J34) -> 17.901563 | K21: =SUM(K22:K34) -> 17.901563 | L21: =SUM(L22:L34) -> 17.901563 | N21: =SUM(N22:N34) -> 86.048406 | O21: =SUM(O22:O34) -> 2512.179 | P21: =SUM(P22:P34) -> 4956.1422 | Q21: =SUM(Q22:Q34) -> 4970.7853 | R21: =SUM(R22:R34) -> 5006.8561 | S21: =SUM(S22:S34) -> 5013.4966 | T21: =SUM(T22:T34) -> 5047.4538
A22: =+'3 Recursos físicos'!A23 -> Operatividad EVEA | B22: =+'3 Recursos físicos'!E23 -> 225 | C22: =+B22*5% -> 11.25 | D22: 10 | E22: =+(B22-C22)/D22 -> 21.375 | F22: =+E22/2 -> 10.6875 | G22: =+F22 -> 10.6875 | H22: =+G22 -> 10.6875 | I22: =+H22 -> 10.6875 | J22: =+I22 -> 10.6875 | K22: =+J22 -> 10.6875 | L22: =+K22 -> 10.6875 | N22: =+G22+(('3 Recursos físicos'!C145*0.95)/Depreciación!$D22) -> 73.46231 | O22: =+H22+(('3 Recursos físicos'!D145*0.95)/Depreciación!$D22) -> 88.790005 | P22: =+I22+(('3 Recursos físicos'!E145*0.95)/Depreciación!$D22) -> 124.18487 | Q22: =+J22+(('3 Recursos físicos'!F145*0.95)/Depreciación!$D22) -> 136.57975 | R22: =+K22+(('3 Recursos físicos'!G145*0.95)/Depreciación!$D22) -> 168.61315 | S22: =+L22+(('3 Recursos físicos'!H145*0.95)/Depreciación!$D22) -> 173.5289 | T22: =+F22+(('3 Recursos físicos'!I145*0.95)/Depreciación!$D22) -> 203.55051
A23: =+'3 Recursos físicos'!A24 -> Licencias, almacenamiento y webninar ZOOM | B23: =+'3 Recursos físicos'!E24 -> 151.875 | C23: =+B23*5% -> 7.59375 | D23: 10 | E23: =+(B23-C23)/D23 -> 14.428125 | F23: =+E23/2 -> 7.2140625 | G23: =+F23 -> 7.2140625 | H23: =+G23 -> 7.2140625 | I23: =+H23 -> 7.2140625 | J23: =+I23 -> 7.2140625 | K23: =+J23 -> 7.2140625 | L23: =+K23 -> 7.2140625 | N23: =+G23+(('3 Recursos físicos'!C146*0.95)/Depreciación!$D23) -> 12.586096 | O23: =+H23+(('3 Recursos físicos'!D146*0.95)/Depreciación!$D23) -> 14.426496 | P23: =+I23+(('3 Recursos físicos'!E146*0.95)/Depreciación!$D23) -> 18.307335 | Q23: =+J23+(('3 Recursos físicos'!F146*0.95)/Depreciación!$D23) -> 20.55558 | R23: =+K23+(('3 Recursos físicos'!G146*0.95)/Depreciación!$D23) -> 24.593 | S23: =+L23+(('3 Recursos físicos'!H146*0.95)/Depreciación!$D23) -> 26.317714 | T23: =+F23+(('3 Recursos físicos'!I146*0.95)/Depreciación!$D23) -> 30.253261
A24: =+'3 Recursos físicos'!A25 -> Laboratorio de Redes | B24: =+'3 Recursos físicos'!E25 -> 0 | C24: =+B24*5% -> 0 | D24: 10 | E24: =+(B24-C24)/D24 -> 0 | F24: =+E24/2 -> 0 | G24: =+F24 -> 0 | H24: =+G24 -> 0 | I24: =+H24 -> 0 | J24: =+I24 -> 0 | K24: =+J24 -> 0 | L24: =+K24 -> 0 | N24: =+G24+(('3 Recursos físicos'!C147*0.95)/Depreciación!$D24) -> 0 | O24: =+H24+(('3 Recursos físicos'!D147*0.95)/Depreciación!$D24) -> 2408.9625 | P24: 2406.825 | Q24: 2406.825 | R24: 2406.825 | S24: 2406.825 | T24: 2406.825
A25: =+'3 Recursos físicos'!A26 -> Laboratorio de Redes | B25: =+'3 Recursos físicos'!E26 -> 0 | C25: =+B25*5% -> 0 | D25: 10 | E25: =+(B25-C25)/D25 -> 0 | F25: =+E25/2 -> 0 | G25: =+F25 -> 0 | H25: =+G25 -> 0 | I25: =+H25 -> 0 | J25: =+I25 -> 0 | K25: =+J25 -> 0 | L25: =+K25 -> 0 | N25: =+G25+(('3 Recursos físicos'!C148*0.95)/Depreciación!$D25) -> 0 | O25: =+H25+(('3 Recursos físicos'!D148*0.95)/Depreciación!$D25) -> 0 | P25: 2406.825 | Q25: 2406.825 | R25: 2406.825 | S25: 2406.825 | T25: 2406.825
A26: =+'3 Recursos físicos'!A27 -> 0 | B26: =+'3 Recursos físicos'!E27 -> 0 | C26: =+B26*5% -> 0 | D26: 10 | E26: =+(B26-C26)/D26 -> 0 | F26: =+E26/2 -> 0 | G26: =+F26 -> 0 | H26: =+G26 -> 0 | I26: =+H26 -> 0 | J26: =+I26 -> 0 | K26: =+J26 -> 0 | L26: =+K26 -> 0 | N26: =+G26+(('3 Recursos físicos'!C161*0.95)/Depreciación!$D26) -> 0 | O26: =+H26+(('3 Recursos físicos'!D161*0.95)/Depreciación!$D26) -> 0 | P26: =+I26+(('3 Recursos físicos'!E161*0.95)/Depreciación!$D26) -> 0 | Q26: =+J26+(('3 Recursos físicos'!F161*0.95)/Depreciación!$D26) -> 0 | R26: =+K26+(('3 Recursos físicos'!G161*0.95)/Depreciación!$D26) -> 0 | S26: =+L26+(('3 Recursos físicos'!H161*0.95)/Depreciación!$D26)+R26 -> 0 | T26: =+M26+(('3 Recursos físicos'!I161*0.95)/Depreciación!$D26)+S26 -> 0
A27: =+'3 Recursos físicos'!A29 -> Equipo de audio | B27: =+'3 Recursos físicos'!E31 -> 0 | C27: =+B27*5% -> 0 | D27: 10 | E27: =+(B27-C27)/D27 -> 0 | F27: =+E27/2 -> 0 | G27: =+F27 -> 0 | H27: =+G27 -> 0 | I27: =+H27 -> 0 | J27: =+I27 -> 0 | K27: =+J27 -> 0 | L27: =+K27 -> 0 | N27: =+G27+(('3 Recursos físicos'!C163*0.95)/Depreciación!$D27) -> 0 | O27: =+H27+(('3 Recursos físicos'!D163*0.95)/Depreciación!$D27) -> 0 | P27: =+I27+(('3 Recursos físicos'!E163*0.95)/Depreciación!$D27) -> 0 | Q27: =+J27+(('3 Recursos físicos'!F163*0.95)/Depreciación!$D27) -> 0 | R27: =+K27+(('3 Recursos físicos'!G163*0.95)/Depreciación!$D27) -> 0 | S27: =+L27+(('3 Recursos físicos'!H163*0.95)/Depreciación!$D27) -> 0 | T27: =+N27+(('3 Recursos físicos'!I163*0.95)/Depreciación!$D27) -> 0
A28: =+'3 Recursos físicos'!A30 -> 0 | B28: =+'3 Recursos físicos'!E32 -> 0 | C28: =+B28*5% -> 0 | D28: 10 | E28: =+(B28-C28)/D28 -> 0 | F28: =+E28/2 -> 0 | G28: =+F28 -> 0 | H28: =+G28 -> 0 | I28: =+H28 -> 0 | J28: =+I28 -> 0 | K28: =+J28 -> 0 | L28: =+K28 -> 0 | N28: =+G28+(('3 Recursos físicos'!C164*0.95)/Depreciación!$D28) -> 0 | O28: =+H28+(('3 Recursos físicos'!D164*0.95)/Depreciación!$D28) -> 0 | P28: =+I28+(('3 Recursos físicos'!E164*0.95)/Depreciación!$D28) -> 0 | Q28: =+J28+(('3 Recursos físicos'!F164*0.95)/Depreciación!$D28) -> 0 | R28: =+K28+(('3 Recursos físicos'!G164*0.95)/Depreciación!$D28) -> 0 | S28: =+L28+(('3 Recursos físicos'!H164*0.95)/Depreciación!$D28) -> 0 | T28: =+M28+(('3 Recursos físicos'!I164*0.95)/Depreciación!$D28) -> 0
A29: =+'3 Recursos físicos'!A33 -> 0 | B29: =+'3 Recursos físicos'!E33 -> 0 | C29: =+B29*5% -> 0 | D29: 10 | E29: =+(B29-C29)/D29 -> 0 | F29: =+E29/2 -> 0 | G29: =+F29 -> 0 | H29: =+G29 -> 0 | I29: =+H29 -> 0 | J29: =+I29 -> 0 | K29: =+J29 -> 0 | L29: =+K29 -> 0 | N29: =+G29+(('3 Recursos físicos'!C165*0.95)/Depreciación!$D29) -> 0 | O29: =+H29+(('3 Recursos físicos'!D165*0.95)/Depreciación!$D29) -> 0 | P29: =+I29+(('3 Recursos físicos'!E165*0.95)/Depreciación!$D29) -> 0 | Q29: =+J29+(('3 Recursos físicos'!F165*0.95)/Depreciación!$D29) -> 0 | R29: =+K29+(('3 Recursos físicos'!G165*0.95)/Depreciación!$D29) -> 0 | S29: =+L29+(('3 Recursos físicos'!H165*0.95)/Depreciación!$D29) -> 0 | T29: =+N29+(('3 Recursos físicos'!I165*0.95)/Depreciación!$D29) -> 0
A30: =+'3 Recursos físicos'!A34 -> 0 | B30: =+'3 Recursos físicos'!E34 -> 0 | C30: =+B30*5% -> 0 | D30: 10 | E30: =+(B30-C30)/D30 -> 0 | F30: =+E30/2 -> 0 | G30: =+F30 -> 0 | H30: =+G30 -> 0 | I30: =+H30 -> 0 | J30: =+I30 -> 0 | K30: =+J30 -> 0 | L30: =+K30 -> 0 | N30: =+G30+(('3 Recursos físicos'!C166*0.95)/Depreciación!$D30) -> 0 | O30: =+H30+(('3 Recursos físicos'!D166*0.95)/Depreciación!$D30) -> 0 | P30: =+I30+(('3 Recursos físicos'!E166*0.95)/Depreciación!$D30) -> 0 | Q30: =+J30+(('3 Recursos físicos'!F166*0.95)/Depreciación!$D30) -> 0 | R30: =+K30+(('3 Recursos físicos'!G166*0.95)/Depreciación!$D30) -> 0 | S30: =+L30+(('3 Recursos físicos'!H166*0.95)/Depreciación!$D30) -> 0 | T30: =+N30+(('3 Recursos físicos'!I166*0.95)/Depreciación!$D30) -> 0
A31: =+'3 Recursos físicos'!A35 -> 0 | B31: =+'3 Recursos físicos'!E35 -> 0 | C31: =+B31*5% -> 0 | D31: 10 | E31: =+(B31-C31)/D31 -> 0 | F31: =+E31/2 -> 0 | G31: =+F31 -> 0 | H31: =+G31 -> 0 | I31: =+H31 -> 0 | J31: =+I31 -> 0 | K31: =+J31 -> 0 | L31: =+K31 -> 0 | N31: =+G31+(('3 Recursos físicos'!C167*0.95)/Depreciación!$D31) -> 0 | O31: =+H31+(('3 Recursos físicos'!D167*0.95)/Depreciación!$D31) -> 0 | P31: =+I31+(('3 Recursos físicos'!E167*0.95)/Depreciación!$D31) -> 0 | Q31: =+J31+(('3 Recursos físicos'!F167*0.95)/Depreciación!$D31) -> 0 | R31: =+K31+(('3 Recursos físicos'!G167*0.95)/Depreciación!$D31) -> 0 | S31: =+L31+(('3 Recursos físicos'!H167*0.95)/Depreciación!$D31) -> 0 | T31: =+N31+(('3 Recursos físicos'!I167*0.95)/Depreciación!$D31) -> 0
A32: =+'3 Recursos físicos'!A37 -> 0 | B32: =+'3 Recursos físicos'!E37 -> 0 | C32: =+B32*5% -> 0 | D32: 10 | E32: =+(B32-C32)/D32 -> 0 | F32: =+E32/2 -> 0 | G32: =+F32 -> 0 | H32: =+G32 -> 0 | I32: =+H32 -> 0 | J32: =+I32 -> 0 | K32: =+J32 -> 0 | L32: =+K32 -> 0 | N32: =+G32+(('3 Recursos físicos'!C169*0.95)/Depreciación!$D32) -> 0 | O32: =+H32+(('3 Recursos físicos'!D169*0.95)/Depreciación!$D32) -> 0 | P32: =+I32+(('3 Recursos físicos'!E169*0.95)/Depreciación!$D32) -> 0 | Q32: =+J32+(('3 Recursos físicos'!F169*0.95)/Depreciación!$D32) -> 0 | R32: =+K32+(('3 Recursos físicos'!G169*0.95)/Depreciación!$D32) -> 0 | S32: =+L32+(('3 Recursos físicos'!H169*0.95)/Depreciación!$D32) -> 0 | T32: =+N32+(('3 Recursos físicos'!I169*0.95)/Depreciación!$D32) -> 0
A33: =+'3 Recursos físicos'!A38 -> 0 | B33: =+'3 Recursos físicos'!E38 -> 0 | C33: =+B33*5% -> 0 | D33: 10 | E33: =+(B33-C33)/D33 -> 0 | F33: =+E33/2 -> 0 | G33: =+F33 -> 0 | H33: =+G33 -> 0 | I33: =+H33 -> 0 | J33: =+I33 -> 0 | K33: =+J33 -> 0 | L33: =+K33 -> 0 | N33: =+G33+(('3 Recursos físicos'!C170*0.95)/Depreciación!$D33) -> 0 | O33: =+H33+(('3 Recursos físicos'!D170*0.95)/Depreciación!$D33) -> 0 | P33: =+I33+(('3 Recursos físicos'!E170*0.95)/Depreciación!$D33) -> 0 | Q33: =+J33+(('3 Recursos físicos'!F170*0.95)/Depreciación!$D33) -> 0 | R33: =+K33+(('3 Recursos físicos'!G170*0.95)/Depreciación!$D33) -> 0 | S33: =+L33+(('3 Recursos físicos'!H170*0.95)/Depreciación!$D33) -> 0 | T33: =+N33+(('3 Recursos físicos'!I170*0.95)/Depreciación!$D33) -> 0
A34: =+'3 Recursos físicos'!A39 -> 0 | B34: =+'3 Recursos físicos'!E39 -> 0 | C34: =+B34*5% -> 0 | D34: 10 | E34: =+(B34-C34)/D34 -> 0 | F34: =+E34/2 -> 0 | G34: =+F34 -> 0 | H34: =+G34 -> 0 | I34: =+H34 -> 0 | J34: =+I34 -> 0 | K34: =+J34 -> 0 | L34: =+K34 -> 0 | N34: =+G34+(('3 Recursos físicos'!C171*0.95)/Depreciación!$D34) -> 0 | O34: =+H34+(('3 Recursos físicos'!D171*0.95)/Depreciación!$D34) -> 0 | P34: =+I34+(('3 Recursos físicos'!E171*0.95)/Depreciación!$D34) -> 0 | Q34: =+J34+(('3 Recursos físicos'!F171*0.95)/Depreciación!$D34) -> 0 | R34: =+K34+(('3 Recursos físicos'!G171*0.95)/Depreciación!$D34) -> 0 | S34: =+L34+(('3 Recursos físicos'!H171*0.95)/Depreciación!$D34) -> 0 | T34: =+M34+(('3 Recursos físicos'!I171*0.95)/Depreciación!$D34) -> 0
A35: =+'3 Recursos físicos'!A40 -> Equipo de Computo | E35: =SUM(E36:E50) -> 380 | F35: =SUM(F36:F50) -> 190 | G35: =SUM(G36:G50) -> 190 | H35: =SUM(H36:H50) -> 190 | I35: =SUM(I36:I50) -> 190 | J35: =SUM(J36:J50) -> 190 | K35: =SUM(K36:K50) -> 190 | L35: =SUM(L36:L50) -> 190 | N35: =SUM(N36:N50) -> 190 | O35: =SUM(O36:O50) -> 190 | P35: =SUM(P36:P50) -> 190 | Q35: =SUM(Q36:Q50) -> 190 | R35: =SUM(R36:R50) -> 190 | S35: =SUM(S36:S50) -> 190 | T35: =SUM(T36:T50) -> 0
A36: =+'3 Recursos físicos'!A41 -> Pizarra digital | B36: =+'3 Recursos físicos'!E41 -> 0 | C36: =+B36*5% -> 0 | D36: 3 | E36: =+(B36-C36)/D36 -> 0 | F36: =+E36/2 -> 0 | G36: =+F36 -> 0 | H36: =+G36 -> 0 | I36: =+H36 -> 0 | J36: =+I36 -> 0 | K36: =+J36 -> 0 | L36: =+K36 -> 0 | N36: =+G36+(('3 Recursos físicos'!C163*0.95)/Depreciación!$D36) -> 0 | O36: =+H36+(('3 Recursos físicos'!D163*0.95)/Depreciación!$D36) -> 0 | P36: =+I36+(('3 Recursos físicos'!E163*0.95)/Depreciación!$D36) -> 0 | Q36: =+J36+(('3 Recursos físicos'!F163*0.95)/Depreciación!$D36) -> 0 | R36: =+K36+(('3 Recursos físicos'!G163*0.95)/Depreciación!$D36) -> 0 | S36: =+L36+(('3 Recursos físicos'!H163*0.95)/Depreciación!$D36) -> 0 | T36: =+F36+(('3 Recursos físicos'!I163*0.95)/Depreciación!$D36) -> 0
A37: =+'3 Recursos físicos'!A42 -> Perifericos | B37: =+'3 Recursos físicos'!E42 -> 0 | C37: =+B37*5% -> 0 | D37: 3 | E37: =+(B37-C37)/D37 -> 0 | F37: =+E37/2 -> 0 | G37: =+F37 -> 0 | H37: =+G37 -> 0 | I37: =+H37 -> 0 | J37: =+I37 -> 0 | K37: =+J37 -> 0 | L37: =+K37 -> 0 | N37: =+G37+(('3 Recursos físicos'!C164*0.95)/Depreciación!$D37) -> 0 | O37: =+H37+(('3 Recursos físicos'!D164*0.95)/Depreciación!$D37) -> 0 | P37: =+I37+(('3 Recursos físicos'!E164*0.95)/Depreciación!$D37) -> 0 | Q37: =+J37+(('3 Recursos físicos'!F164*0.95)/Depreciación!$D37) -> 0 | R37: =+K37+(('3 Recursos físicos'!G164*0.95)/Depreciación!$D37) -> 0 | S37: =+L37+(('3 Recursos físicos'!H164*0.95)/Depreciación!$D37) -> 0 | T37: =+M37+(('3 Recursos físicos'!I164*0.95)/Depreciación!$D37) -> 0
A38: =+'3 Recursos físicos'!A43 -> Proyectores | B38: =+'3 Recursos físicos'!E43 -> 0 | C38: =+B38*5% -> 0 | D38: 3 | E38: =+(B38-C38)/D38 -> 0 | F38: =+E38/2 -> 0 | G38: =+F38 -> 0 | H38: =+G38 -> 0 | I38: =+H38 -> 0 | J38: =+I38 -> 0 | K38: =+J38 -> 0 | L38: =+K38 -> 0 | N38: =+G38+(('3 Recursos físicos'!C165*0.95)/Depreciación!$D38) -> 0 | O38: =+H38+(('3 Recursos físicos'!D165*0.95)/Depreciación!$D38) -> 0 | P38: =+I38+(('3 Recursos físicos'!E165*0.95)/Depreciación!$D38) -> 0 | Q38: =+J38+(('3 Recursos físicos'!F165*0.95)/Depreciación!$D38) -> 0 | R38: =+K38+(('3 Recursos físicos'!G165*0.95)/Depreciación!$D38) -> 0 | S38: =+L38+(('3 Recursos físicos'!H165*0.95)/Depreciación!$D38) -> 0 | T38: =+N38+(('3 Recursos físicos'!I165*0.95)/Depreciación!$D38) -> 0
A39: =+'3 Recursos físicos'!A44 -> Computador escritorio | B39: =+'3 Recursos físicos'!E44 -> 0 | C39: =+B39*5% -> 0 | D39: 3 | E39: =+(B39-C39)/D39 -> 0 | F39: =+E39/2 -> 0 | G39: =+F39 -> 0 | H39: =+G39 -> 0 | I39: =+H39 -> 0 | J39: =+I39 -> 0 | K39: =+J39 -> 0 | L39: =+K39 -> 0 | N39: =+G39+(('3 Recursos físicos'!C166*0.95)/Depreciación!$D39) -> 0 | O39: =+H39+(('3 Recursos físicos'!D166*0.95)/Depreciación!$D39) -> 0 | P39: =+I39+(('3 Recursos físicos'!E166*0.95)/Depreciación!$D39) -> 0 | Q39: =+J39+(('3 Recursos físicos'!F166*0.95)/Depreciación!$D39) -> 0 | R39: =+K39+(('3 Recursos físicos'!G166*0.95)/Depreciación!$D39) -> 0 | S39: =+L39+(('3 Recursos físicos'!H166*0.95)/Depreciación!$D39) -> 0 | T39: =+N39+(('3 Recursos físicos'!I166*0.95)/Depreciación!$D39) -> 0
A40: =+'3 Recursos físicos'!A45 -> Software | B40: =+'3 Recursos físicos'!E45 -> 0 | C40: =+B40*5% -> 0 | D40: 3 | E40: =+(B40-C40)/D40 -> 0 | F40: =+E40/2 -> 0 | G40: =+F40 -> 0 | H40: =+G40 -> 0 | I40: =+H40 -> 0 | J40: =+I40 -> 0 | K40: =+J40 -> 0 | L40: =+K40 -> 0 | N40: =+G40+(('3 Recursos físicos'!C167*0.95)/Depreciación!$D40) -> 0 | O40: =+H40+(('3 Recursos físicos'!D167*0.95)/Depreciación!$D40) -> 0 | P40: =+I40+(('3 Recursos físicos'!E167*0.95)/Depreciación!$D40) -> 0 | Q40: =+J40+(('3 Recursos físicos'!F167*0.95)/Depreciación!$D40) -> 0 | R40: =+K40+(('3 Recursos físicos'!G167*0.95)/Depreciación!$D40) -> 0 | S40: =+L40+(('3 Recursos físicos'!H167*0.95)/Depreciación!$D40) -> 0 | T40: =+M40+(('3 Recursos físicos'!I167*0.95)/Depreciación!$D40) -> 0
...

Sheet 7 Sueldos
B1: =+'1 Estudiantes'!B3 -> 2023 | E1: INFLACIÓN | F1: 1 | K1: estudiantes U. académica | L1: 285
B2: PESO | C2: Nº | D2: CARGO | E2: SUELDO MENSUAL | F2: DECIMO XIII | G2: DECIMO IV | H2: VACACIONES | I2: FONDOS DE RESERVA MENSUAL | J2: APORTE PATRONAL MENSUAL | K2: TOTAL
B3: =+L3/M3 -> 0.095238095 | C3: 1 | D3: =+'6 Capital de trabajo'!B4 -> Decano | E3: =+'6 Capital de trabajo'!C4 -> 3880 | F3: =+E3*12/12/2 -> 1940 | G3: =+(400/2)*$F$1 -> 200 | H3: =+E3*12/24/2 -> 970 | I3: =+E3*8.33% -> 323.204 | J3: =+E3*11.15% -> 432.62 | K3: =+((((E3+I3+J3)*6)+F3+G3+H3)*C3)*B3 -> 2945.2328 | L3: ='1 Estudiantes'!$B$12 -> 30 | M3: =+$L$1+L3 -> 315
B4: =+L4/M4 -> 0.095238095 | C4: 1 | D4: =+'6 Capital de trabajo'!B5 -> Subdecano | E4: =+'6 Capital de trabajo'!C5 -> 2880 | F4: =+E4*12/12/2 -> 1440 | G4: =+(400/2)*$F$1 -> 200 | H4: =+E4*12/24/2 -> 720 | I4: =+E4*8.33% -> 239.904 | J4: =+E4*11.15% -> 321.12 | K4: =+((((E4+I4+J4)*6)+F4+G4+H4)*C4)*B4 -> 2191.0613 | L4: ='1 Estudiantes'!$B$12 -> 30 | M4: =+$L$1+L4 -> 315
B5: 1 | C5: 1 | D5: =+'6 Capital de trabajo'!B6 -> Director de Carrera | E5: =+'6 Capital de trabajo'!C6 -> 2200 | F5: =+E5*12/12/2 -> 1100 | G5: =+(400/2)*$F$1 -> 200 | H5: =+E5*12/24/2 -> 550 | I5: =+E5*8.33% -> 183.26 | J5: =+E5*11.15% -> 245.3 | K5: =+((((E5+I5+J5)*6)+F5+G5+H5)*C5)*B5 -> 17621.36 | L5: ='1 Estudiantes'!$B$12 -> 30 | M5: =+$L$1+L5 -> 315
B6: =+L6/M6 -> 0.095238095 | C6: 1 | D6: =+'6 Capital de trabajo'!B7 -> Secretario | E6: =+'6 Capital de trabajo'!C7 -> 1000 | F6: =+E6*12/12/2 -> 500 | G6: =+(400/2)*$F$1 -> 200 | H6: =+E6*12/24/2 -> 250 | I6: =+E6*8.33% -> 83.3 | J6: =+E6*11.15% -> 111.5 | K6: =+((((E6+I6+J6)*6)+F6+G6+H6)*C6)*B6 -> 773.21905 | L6: ='1 Estudiantes'!$B$12 -> 30 | M6: =+$L$1+L6 -> 315
B7: =+L7/M7 -> 0.095238095 | C7: 1 | D7: =+'6 Capital de trabajo'!B8 -> Auxiliar de Secretaria | E7: =+'6 Capital de trabajo'!C8 -> 850 | F7: =+E7*12/12/2 -> 425 | G7: =+(400/2)*$F$1 -> 200 | H7: =+E7*12/24/2 -> 212.5 | I7: =+E7*8.33% -> 70.805 | J7: =+E7*11.15% -> 94.775 | K7: =+((((E7+I7+J7)*6)+F7+G7+H7)*C7)*B7 -> 660.09333 | L7: ='1 Estudiantes'!$B$12 -> 30 | M7: =+$L$1+L7 -> 315
B8: =+L8/M8 -> 0.095238095 | C8: 1 | D8: =+'6 Capital de trabajo'!B9 -> Coordinador | E8: =+'6 Capital de trabajo'!C9 -> 900 | F8: =+E8*12/12/2 -> 450 | G8: =+(400/2)*$F$1 -> 200 | H8: =+E8*12/24/2 -> 225 | I8: =+E8*8.33% -> 74.97 | J8: =+E8*11.15% -> 100.35 | K8: =+((((E8+I8+J8)*6)+F8+G8+H8)*C8)*B8 -> 697.8019 | L8: ='1 Estudiantes'!$B$12 -> 30 | M8: =+$L$1+L8 -> 315
B9: =+L9/M9 -> 0.095238095 | C9: 1 | D9: =+'6 Capital de trabajo'!B10 -> Bienestar Estudiantil | E9: =+'6 Capital de trabajo'!C10 -> 900 | F9: =+E9*12/12/2 -> 450 | G9: =+(400/2)*$F$1 -> 200 | H9: =+E9*12/24/2 -> 225 | I9: =+E9*8.33% -> 74.97 | J9: =+E9*11.15% -> 100.35 | K9: =+((((E9+I9+J9)*6)+F9+G9+H9)*C9)*B9 -> 697.8019 | L9: ='1 Estudiantes'!$B$12 -> 30 | M9: =+$L$1+L9 -> 315
B10: 1 | C10: =+'5 Demanda'!B15 -> 0.24 | D10: =+'6 Capital de trabajo'!B11 -> Tiempo Completo PhD | E10: =+'6 Capital de trabajo'!C11 -> 2800 | F10: =+E10*12/12/2 -> 1400 | G10: =+(400/2)*$F$1 -> 200 | H10: =+E10*12/24/2 -> 700 | I10: =+E10*8.33% -> 233.24 | J10: =+E10*11.15% -> 312.2 | K10: =+((((E10+I10+J10)*6)+F10+G10+H10)*C10)*B10 -> 5369.4336 | L10: ='1 Estudiantes'!$B$12 -> 30 | M10: =+$L$1+L10 -> 315
B11: 1 | C11: =+'5 Demanda'!B16 -> 0.6 | D11: =+'6 Capital de trabajo'!B12 -> Tiempo Completo Mgs. | E11: =+'6 Capital de trabajo'!C12 -> 1800 | F11: =+E11*12/12/2 -> 900 | G11: =+(400/2)*$F$1 -> 200 | H11: =+E11*12/24/2 -> 450 | I11: =+E11*8.33% -> 149.94 | J11: =+E11*11.15% -> 200.7 | K11: =+((((E11+I11+J11)*6)+F11+G11+H11)*C11)*B11 -> 8672.304 | L11: ='1 Estudiantes'!$B$12 -> 30 | M11: =+$L$1+L11 -> 315
B12: 1 | C12: =+'5 Demanda'!B17 -> 0 | D12: =+'6 Capital de trabajo'!B13 -> Medio Tiempo | E12: =+'6 Capital de trabajo'!C13 -> 900 | F12: =+E12*12/12/2 -> 450 | G12: =+(400/2)*$F$1 -> 200 | H12: =+E12*12/24/2 -> 225 | I12: =+E12*8.33% -> 74.97 | J12: =+E12*11.15% -> 100.35 | K12: =+((((E12+I12+J12)*6)+F12+G12+H12)*C12)*B12 -> 0 | L12: ='1 Estudiantes'!$B$12 -> 30 | M12: =+$L$1+L12 -> 315
B13: 1 | C13: =+'5 Demanda'!B18 -> 0.16 | D13: =+'6 Capital de trabajo'!B14 -> Tiempo Parcial | E13: =+'6 Capital de trabajo'!C14 -> 432 | F13: =+E13*12/12/2 -> 216 | G13: =+(400/2)*$F$1 -> 200 | H13: =+E13*12/24/2 -> 108 | I13: =+E13*8.33% -> 35.9856 | J13: =+E13*11.15% -> 48.168 | K13: =+((((E13+I13+J13)*6)+F13+G13+H13)*C13)*B13 -> 579.34746 | L13: ='1 Estudiantes'!$B$12 -> 30 | M13: =+$L$1+L13 -> 315
B14: 1 | C14: =+'1 Estudiantes'!B30 -> 0.25 | D14: =+'1 Estudiantes'!A30 -> Ocasional Tipo 2 (Técnico Docente) | E14: =+'6 Capital de trabajo'!C15 -> 1350 | F14: =+E14*12/12/2 -> 675 | G14: =+(400/2)*$F$1 -> 200 | H14: =+E14*12/24/2 -> 337.5 | I14: =+E14*8.33% -> 112.455 | J14: =+E14*11.15% -> 150.525 | K14: =+((((E14+I14+J14)*6)+F14+G14+H14)*C14)*B14 -> 2722.595 | L14: ='1 Estudiantes'!$B$12 -> 30 | M14: =+$L$1+L14 -> 315
B15: =+L15/M15 -> 0.095238095 | C15: 1 | D15: =+'6 Capital de trabajo'!B16 -> Bibliotecario | E15: =+'6 Capital de trabajo'!C16 -> 800 | F15: =+E15*12/12/2 -> 400 | G15: =+(400/2)*$F$1 -> 200 | H15: =+E15*12/24/2 -> 200 | I15: =+E15*8.33% -> 66.64 | J15: =+E15*11.15% -> 89.2 | K15: =+((((E15+I15+J15)*6)+F15+G15+H15)*C15)*B15 -> 622.38476 | L15: ='1 Estudiantes'!$B$12 -> 30 | M15: =+$L$1+L15 -> 315
B16: =+L16/M16 -> 0.095238095 | C16: 2 | D16: =+'6 Capital de trabajo'!B17 -> Auxiliar de Servicio | E16: =+'6 Capital de trabajo'!C17 -> 450 | F16: =+E16*12/12/2 -> 225 | G16: =+(400/2)*$F$1 -> 200 | H16: =+E16*12/24/2 -> 112.5 | I16: =+E16*8.33% -> 37.485 | J16: =+E16*11.15% -> 50.175 | K16: =+((((E16+I16+J16)*6)+F16+G16+H16)*C16)*B16 -> 716.84952 | L16: ='1 Estudiantes'!$B$12 -> 30 | M16: =+$L$1+L16 -> 315
B17: =+L17/M17 -> 0.095238095 | C17: 1 | D17: =+'6 Capital de trabajo'!B18 -> Guardia | E17: =+'6 Capital de trabajo'!C18 -> 650 | F17: =+E17*12/12/2 -> 325 | G17: =+(400/2)*$F$1 -> 200 | H17: =+E17*12/24/2 -> 162.5 | I17: =+E17*8.33% -> 54.145 | J17: =+E17*11.15% -> 72.475 | K17: =+((((E17+I17+J17)*6)+F17+G17+H17)*C17)*B17 -> 509.25905 | L17: ='1 Estudiantes'!$B$12 -> 30 | M17: =+$L$1+L17 -> 315
D18: TOTAL | E18: =SUM(E3:E17) -> 21792 | F18: =SUM(F3:F17) -> 10896 | G18: =SUM(G3:G17) -> 3000 | H18: =SUM(H3:H17) -> 5448 | I18: =SUM(I3:I17) -> 1815.2736 | J18: =SUM(J3:J17) -> 2429.808 | K18: =SUM(K3:K17) -> 44778.744
B20: =+'1 Estudiantes'!C3 -> 2023 | E20: INFLACIÓN | F20: =+Inflación!C11/100+1 -> 1.0134 | O20: =475-26 -> 449
C21: =+C2 -> Nº | D21: CARGO | E21: SUELDO MENSUAL | F21: DECIMO XIII | G21: DECIMO IV | H21: VACACIONES | I21: FONDOS DE RESERVA MENSUAL | J21: APORTE PATRONAL MENSUAL | K21: TOTAL | O21: =+O22/P22 -> 0.29093895
B22: =+L22/M22 -> 0.23374738 | C22: =+C3 -> 1 | D22: =+D3 -> Decano | E22: =+E3*$F$20 -> 3931.992 | F22: =+E22*12/12/2 -> 1965.996 | G22: =+(400/2)*$F$1*1.05 -> 210 | H22: =+E22*12/24/2 -> 982.998 | I22: =+E22*8.33% -> 327.53493 | J22: =+E22*11.15% -> 438.41711 | K22: =+((((E22+I22+J22)*6)+F22+G22+H22)*C22)*B22 -> 7327.1992 | L22: =+'1 Estudiantes'!$C$12 -> 86.94 | M22: =+$L$1+L22 -> 371.94 | O22: =+L17+L22 -> 116.94 | P22: =+M17+L22 -> 401.94
B23: =+L23/M23 -> 0.23374738 | C23: =+C4 -> 1 | D23: =+D4 -> Subdecano | E23: =+E4*$F$20 -> 2918.592 | F23: =+E23*12/12/2 -> 1459.296 | G23: =+(400/2)*$F$1*1.05 -> 210 | H23: =+E23*12/24/2 -> 729.648 | I23: =+E23*8.33% -> 243.11871 | J23: =+E23*11.15% -> 325.42301 | K23: =+((((E23+I23+J23)*6)+F23+G23+H23)*C23)*B23 -> 5451.3971 | L23: =+'1 Estudiantes'!$C$12 -> 86.94 | M23: =+$L$1+L23 -> 371.94
B24: =+B5 -> 1 | C24: =+C5 -> 1 | D24: =+D5 -> Director de Carrera | E24: =+E5*$F$20 -> 2229.48 | F24: =+E24*12/12/2 -> 1114.74 | G24: =+(400/2)*$F$1*1.05 -> 210 | H24: =+E24*12/24/2 -> 557.37 | I24: =+E24*8.33% -> 185.71568 | J24: =+E24*11.15% -> 248.58702 | K24: =+((((E24+I24+J24)*6)+F24+G24+H24)*C24)*B24 -> 17864.806 | L24: =+'1 Estudiantes'!$C$12 -> 86.94 | M24: =+$L$1+L24 -> 371.94
B25: =+L25/M25 -> 0.23374738 | C25: =+C6 -> 1 | D25: =+D6 -> Secretario | E25: =+E6*$F$20 -> 1013.4 | F25: =+E25*12/12/2 -> 506.7 | G25: =+(400/2)*$F$1*1.05 -> 210 | H25: =+E25*12/24/2 -> 253.35 | I25: =+E25*8.33% -> 84.41622 | J25: =+E25*11.15% -> 112.9941 | K25: =+((((E25+I25+J25)*6)+F25+G25+H25)*C25)*B25 -> 1924.8891 | L25: =+'1 Estudiantes'!$C$12 -> 86.94 | M25: =+$L$1+L25 -> 371.94
B26: =+L26/M26 -> 0.23374738 | C26: =+C7 -> 1 | D26: =+D7 -> Auxiliar de Secretaria | E26: =+E7*$F$20 -> 861.39 | F26: =+E26*12/12/2 -> 430.695 | G26: =+(400/2)*$F$1*1.05 -> 210 | H26: =+E26*12/24/2 -> 215.3475 | I26: =+E26*8.33% -> 71.753787 | J26: =+E26*11.15% -> 96.044985 | K26: =+((((E26+I26+J26)*6)+F26+G26+H26)*C26)*B26 -> 1643.5188 | L26: =+'1 Estudiantes'!$C$12 -> 86.94 | M26: =+$L$1+L26 -> 371.94
B27: =+L27/M27 -> 0.23374738 | C27: =+C8 -> 1 | D27: =+D8 -> Coordinador | E27: =+E8*$F$20 -> 912.06 | F27: =+E27*12/12/2 -> 456.03 | G27: =+(400/2)*$F$1*1.05 -> 210 | H27: =+E27*12/24/2 -> 228.015 | I27: =+E27*8.33% -> 75.974598 | J27: =+E27*11.15% -> 101.69469 | K27: =+((((E27+I27+J27)*6)+F27+G27+H27)*C27)*B27 -> 1737.3089 | L27: =+'1 Estudiantes'!$C$12 -> 86.94 | M27: =+$L$1+L27 -> 371.94
B28: =+L28/M28 -> 0.23374738 | C28: =+C9 -> 1 | D28: =+D9 -> Bienestar Estudiantil | E28: =+E9*$F$20 -> 912.06 | F28: =+E28*12/12/2 -> 456.03 | G28: =+(400/2)*$F$1*1.05 -> 210 | H28: =+E28*12/24/2 -> 228.015 | I28: =+E28*8.33% -> 75.974598 | J28: =+E28*11.15% -> 101.69469 | K28: =+((((E28+I28+J28)*6)+F28+G28+H28)*C28)*B28 -> 1737.3089 | L28: =+'1 Estudiantes'!$C$12 -> 86.94 | M28: =+$L$1+L28 -> 371.94
B29: =+B10 -> 1 | C29: =+'5 Demanda'!C15 -> 0.8 | D29: =+D10 -> Tiempo Completo PhD | E29: =+E10*$F$20 -> 2837.52 | F29: =+E29*12/12/2 -> 1418.76 | G29: =+(400/2)*$F$1*1.05 -> 210 | H29: =+E29*12/24/2 -> 709.38 | I29: =+E29*8.33% -> 236.36542 | J29: =+E29*11.15% -> 316.38348 | K29: =+((((E29+I29+J29)*6)+F29+G29+H29)*C29)*B29 -> 18143.803 | L29: =+'1 Estudiantes'!$C$12 -> 86.94 | M29: =+$L$1+L29 -> 371.94
B30: =+B11 -> 1 | C30: =+'5 Demanda'!C16 -> 2 | D30: =+D11 -> Tiempo Completo Mgs. | E30: =+E11*$F$20 -> 1824.12 | F30: =+E30*12/12/2 -> 912.06 | G30: =+(400/2)*$F$1*1.05 -> 210 | H30: =+E30*12/24/2 -> 456.03 | I30: =+E30*8.33% -> 151.9492 | J30: =+E30*11.15% -> 203.38938 | K30: =+((((E30+I30+J30)*6)+F30+G30+H30)*C30)*B30 -> 29309.683 | L30: =+'1 Estudiantes'!$C$12 -> 86.94 | M30: =+$L$1+L30 -> 371.94
B31: =+B12 -> 1 | C31: =+'5 Demanda'!C17 -> 0 | D31: =+D12 -> Medio Tiempo | E31: =+E12*$F$20 -> 912.06 | F31: =+E31*12/12/2 -> 456.03 | G31: =+(400/2)*$F$1*1.05 -> 210 | H31: =+E31*12/24/2 -> 228.015 | I31: =+E31*8.33% -> 75.974598 | J31: =+E31*11.15% -> 101.69469 | K31: =+((((E31+I31+J31)*6)+F31+G31+H31)*C31)*B31 -> 0 | L31: =+'1 Estudiantes'!$C$12 -> 86.94 | M31: =+$L$1+L31 -> 371.94
B32: =+B13 -> 1 | C32: =+'5 Demanda'!C18 -> 0.53333333 | D32: =+D13 -> Tiempo Parcial | E32: =+E13*$F$20 -> 437.7888 | F32: =+E32*12/12/2 -> 218.8944 | G32: =+(400/2)*$F$1*1.05 -> 210 | H32: =+E32*12/24/2 -> 109.4472 | I32: =+E32*8.33% -> 36.467807 | J32: =+E32*11.15% -> 48.813451 | K32: =+((((E32+I32+J32)*6)+F32+G32+H32)*C32)*B32 -> 1960.9397 | L32: =+'1 Estudiantes'!$C$12 -> 86.94 | M32: =+$L$1+L32 -> 371.94
B33: =+B14 -> 1 | C33: =+'1 Estudiantes'!C30 -> 0.8 | D33: =+D14 -> Ocasional Tipo 2 (Técnico Docente) | E33: =+E14*$F$20 -> 1368.09 | F33: =+E33*12/12/2 -> 684.045 | G33: =+(400/2)*$F$1*1.05 -> 210 | H33: =+E33*12/24/2 -> 342.0225 | I33: =+E33*8.33% -> 113.9619 | J33: =+E33*11.15% -> 152.54204 | K33: =+((((E33+I33+J33)*6)+F33+G33+H33)*C33)*B33 -> 8834.9049 | L33: =+'1 Estudiantes'!$C$12 -> 86.94 | M33: =+$L$1+L33 -> 371.94
B34: =+L34/M34 -> 0.23374738 | C34: =+C15 -> 1 | D34: =+D15 -> Bibliotecario | E34: =+E15*$F$20 -> 810.72 | F34: =+E34*12/12/2 -> 405.36 | G34: =+(400/2)*$F$1*1.05 -> 210 | H34: =+E34*12/24/2 -> 202.68 | I34: =+E34*8.33% -> 67.532976 | J34: =+E34*11.15% -> 90.39528 | K34: =+((((E34+I34+J34)*6)+F34+G34+H34)*C34)*B34 -> 1549.7286 | L34: =+'1 Estudiantes'!$C$12 -> 86.94 | M34: =+$L$1+L34 -> 371.94
B35: =+L35/M35 -> 0.23374738 | C35: =+C16 -> 2 | D35: =+D16 -> Auxiliar de Servicio | E35: =+E16*$F$20 -> 456.03 | F35: =+E35*12/12/2 -> 228.015 | G35: =+(400/2)*$F$1*1.05 -> 210 | H35: =+E35*12/24/2 -> 114.0075 | I35: =+E35*8.33% -> 37.987299 | J35: =+E35*11.15% -> 50.847345 | K35: =+((((E35+I35+J35)*6)+F35+G35+H35)*C35)*B35 -> 1786.3958 | L35: =+'1 Estudiantes'!$C$12 -> 86.94 | M35: =+$L$1+L35 -> 371.94
B36: =+L36/M36 -> 0.23374738 | C36: =+C17 -> 1 | D36: =+D17 -> Guardia | E36: =+E17*$F$20 -> 658.71 | F36: =+E36*12/12/2 -> 329.355 | G36: =+(400/2)*$F$1*1.05 -> 210 | H36: =+E36*12/24/2 -> 164.6775 | I36: =+E36*8.33% -> 54.870543 | J36: =+E36*11.15% -> 73.446165 | K36: =+((((E36+I36+J36)*6)+F36+G36+H36)*C36)*B36 -> 1268.3583 | L36: =+'1 Estudiantes'!$C$12 -> 86.94 | M36: =+$L$1+L36 -> 371.94
D37: =+D18 -> TOTAL | E37: =SUM(E22:E36) -> 22084.013 | F37: =SUM(F22:F36) -> 11042.006 | G37: =SUM(G22:G36) -> 3150 | H37: =SUM(H22:H36) -> 5521.0032 | I37: =SUM(I22:I36) -> 1839.5983 | K37: =SUM(K22:K36) -> 100540.24
B39: =+'1 Estudiantes'!D3 -> 2024 | E39: INFLACIÓN | F39: =+Inflación!C12/100+1 -> 1.0143
C40: Nº | D40: CARGO | E40: SUELDO MENSUAL | F40: DECIMO XIII | G40: DECIMO IV | H40: VACACIONES | I40: FONDOS DE RESERVA MENSUAL | J40: APORTE PATRONAL MENSUAL | K40: TOTAL
B41: =+L41/M41 -> 0.27494222 | C41: =+C3 -> 1 | D41: =+D22 -> Decano | E41: =+E22 -> 3931.992 | F41: =+E41*12/12/2 -> 1965.996 | G41: =+G22 -> 210 | H41: =+E41*12/24/2 -> 982.998 | I41: =+E41*8.33% -> 327.53493 | J41: =+E41*11.15% -> 438.41711 | K41: =+((((E41+I41+J41)*6)+F41+G41+H41)*C41)*B41 -> 8618.5197 | L41: =+'1 Estudiantes'!$D$12 -> 108.07212 | M41: =+$L$1+L41 -> 393.07212
B42: =+L42/M42 -> 0.27494222 | C42: =+C4 -> 1 | D42: =+D23 -> Subdecano | E42: =+E23 -> 2918.592 | F42: =+E42*12/12/2 -> 1459.296 | G42: =+G23 -> 210 | H42: =+E42*12/24/2 -> 729.648 | I42: =+E42*8.33% -> 243.11871 | J42: =+E42*11.15% -> 325.42301 | K42: =+((((E42+I42+J42)*6)+F42+G42+H42)*C42)*B42 -> 6412.1326 | L42: =+'1 Estudiantes'!$D$12 -> 108.07212 | M42: =+$L$1+L42 -> 393.07212
...

Sheet Hoja2
B2: No. Alumnos | C2: 60 | D2: 113.7 | E2: 161.7615 | F2: 209.823 | G2: 257.8845 | H2: 305.946 | I2: 354.0075 | J2: 402.069
B3: CARGO/DEPARTAMENTO | C3: 2020 | D3: 2021 | E3: 2021 | F3: 2022 | G3: 2022 | H3: 2023 | I3: 2023 | J3: 2024
A4: ='Planta central'!A4 -> Auditoría | B4: =+UPPER(A4) -> AUDITORÍA | C4: =SUBTOTAL(9,'Planta central'!M4:M8) -> 96.168571 | D4: =SUBTOTAL(9,'Planta central'!N4:N8) -> 278.69652 | E4: =SUBTOTAL(9,'Planta central'!O4:O8) -> 346.43804 | F4: =SUBTOTAL(9,'Planta central'!P4:P8) -> 503.43851 | G4: =SUBTOTAL(9,'Planta central'!Q4:Q8) -> 548.25635 | H4: =SUBTOTAL(9,'Planta central'!R4:R8) -> 687.76068 | I4: =SUBTOTAL(9,'Planta central'!S4:S8) -> 722.88318 | J4: =SUBTOTAL(9,'Planta central'!T4:T8) -> 856.15465
A5: ='Planta central'!A5 -> 0
A6: ='Planta central'!A6 -> 0
A7: ='Planta central'!A7 -> 0
A8: ='Planta central'!A8 -> 0
A9: ='Planta central'!A9 -> TITULACION Y REGISTRO | B9: =+UPPER(A9) -> TITULACION Y REGISTRO | C9: =SUBTOTAL(9,'Planta central'!M9:M13) -> 81.230404 | D9: =SUBTOTAL(9,'Planta central'!N9:N13) -> 235.40571 | E9: =SUBTOTAL(9,'Planta central'!O9:O13) -> 292.62473 | F9: =SUBTOTAL(9,'Planta central'!P9:P13) -> 425.23782 | G9: =SUBTOTAL(9,'Planta central'!Q9:Q13) -> 463.09397 | H9: =SUBTOTAL(9,'Planta central'!R9:R13) -> 580.92865 | I9: =SUBTOTAL(9,'Planta central'!S9:S13) -> 610.59546 | J9: =SUBTOTAL(9,'Planta central'!T9:T13) -> 723.16545
A10: ='Planta central'!A10 -> 0
